<sdf version='1.6'>
  <model name='cr2'>
    <static>true</static>
    <plugin name='sample' filename='libmove_object_plugin.so'/>
    <link name='base_link'>
      <pose frame=''>0 0 0 0 -0 0</pose>
      <inertial>
        <pose frame=''>0.004161 0 0.135964 0 -0 0</pose>
        <mass>14.419</mass>
        <inertia>
          <ixx>1.02732</ixx>
          <ixy>3.99595e-13</ixy>
          <ixz>-0.00984216</ixz>
          <iyy>1.10989</iyy>
          <iyz>-1.94517e-18</iyz>
          <izz>0.348646</izz>
        </inertia>
      </inertial>
      <collision name='base_link_fixed_joint_lump__base_platform_collision'>
        <pose frame=''>0 0 0 1.5708 -0 1.5708</pose>
        <geometry>
          <box>
            <size>0.25 0.05 0.38</size>
          </box>
        </geometry>
      </collision>
      <collision name='base_link_fixed_joint_lump__body_collision_1'>
        <pose frame=''>0.02 0 0.3 1.5708 -0 1.5708</pose>
        <geometry>
          <box>
            <size>0.486 0.6 0.525</size>
          </box>
        </geometry>
      </collision>
      <collision name='base_link_fixed_joint_lump__head_collision_2'>
        <pose frame=''>0 0 0.75 1.5708 -0 1.5708</pose>
        <geometry>
          <box>
            <size>0.486 0.26 0.525</size>
          </box>
        </geometry>
      </collision>
      <collision name='base_link_fixed_joint_lump__laser_link_collision_3'>
        <pose frame=''>0 0 0.59 0 -0 0</pose>
        <geometry>
          <cylinder>
            <length>0.041</length>
            <radius>0.038</radius>
          </cylinder>
        </geometry>
      </collision>
      <collision name='base_link_fixed_joint_lump__laser_oscillator_collision_4'>
        <pose frame=''>0 0 0.6055 0 -0 -3.14159</pose>
        <geometry>
          <cylinder>
            <length>0.001</length>
            <radius>0.038</radius>
          </cylinder>
        </geometry>
        <surface>
          <contact>
            <ode/>
          </contact>
          <friction>
            <ode/>
          </friction>
        </surface>
      </collision>
      <collision name='base_link_fixed_joint_lump__pillar_FRONT_LEFT_link_collision_5'>
        <pose frame=''>0.1825 0.173 0.6 0 -0 0</pose>
        <geometry>
          <cylinder>
            <length>0.02</length>
            <radius>0.006</radius>
          </cylinder>
        </geometry>
      </collision>
      <collision name='base_link_fixed_joint_lump__pillar_FRONT_RIGHT_link_collision_6'>
        <pose frame=''>0.1825 -0.173 0.6 0 -0 0</pose>
        <geometry>
          <cylinder>
            <length>0.02</length>
            <radius>0.006</radius>
          </cylinder>
        </geometry>
      </collision>
      <collision name='base_link_fixed_joint_lump__pillar_REAR_LEFT_link_collision_7'>
        <pose frame=''>-0.1825 0.173 0.6 0 -0 0</pose>
        <geometry>
          <cylinder>
            <length>0.02</length>
            <radius>0.006</radius>
          </cylinder>
        </geometry>
      </collision>
      <collision name='base_link_fixed_joint_lump__pillar_REAR_RIGHT_link_collision_8'>
        <pose frame=''>-0.1825 -0.173 0.6 0 -0 0</pose>
        <geometry>
          <cylinder>
            <length>0.02</length>
            <radius>0.006</radius>
          </cylinder>
        </geometry>
      </collision>
      <visual name='base_link_fixed_joint_lump__base_platform_visual'>
        <pose frame=''>0 0 0 1.5708 -0 1.5708</pose>
        <geometry>
          <box>
            <size>0.25 0.05 0.38</size>
          </box>
        </geometry>
      </visual>
      <visual name='base_link_fixed_joint_lump__body_visual_1'>
        <pose frame=''>0.27 -0.24 0 1.5708 -0 -3.14159</pose>
        <geometry>
          <mesh>
            <scale>0.001 0.001 0.001</scale>
            <uri>model://cr2/meshes/body.stl</uri>
          </mesh>
        </geometry>
      </visual>
      <visual name='base_link_fixed_joint_lump__back_cover_visual_2'>
        <pose frame=''>-0.245 0.229 0 1.50987 0 -1.5708</pose>
        <geometry>
          <mesh>
            <scale>0.001 0.001 0.001</scale>
            <uri>model://cr2/meshes/back_cover.stl</uri>
          </mesh>
        </geometry>
      </visual>
      <visual name='base_link_fixed_joint_lump__head_visual_3'>
        <pose frame=''>0.24 -0.215 0.02 1.5708 -0 -3.14159</pose>
        <geometry>
          <mesh>
            <scale>0.001 0.001 0.001</scale>
            <uri>model://cr2/meshes/head.stl</uri>
          </mesh>
        </geometry>
      </visual>
      <visual name='base_link_fixed_joint_lump__laser_link_visual_4'>
        <pose frame=''>0 0 0.59 0 -0 0</pose>
        <geometry>
          <cylinder>
            <length>0.041</length>
            <radius>0.038</radius>
          </cylinder>
        </geometry>
      </visual>
      <visual name='base_link_fixed_joint_lump__laser_oscillator_visual_5'>
        <pose frame=''>0 0 0.6055 0 -0 -3.14159</pose>
        <geometry>
          <cylinder>
            <length>0.001</length>
            <radius>0.038</radius>
          </cylinder>
        </geometry>
        <material>
          <script>
            <name>Gazebo/Green</name>
            <uri>file://media/materials/scripts/gazebo.material</uri>
          </script>
        </material>
      </visual>
      <visual name='base_link_fixed_joint_lump__monitor_visual_6'>
        <pose frame=''>0.228 -0 0.76 1.5708 1.45772 0</pose>
        <geometry>
          <box>
            <size>0.13 0.001 0.16</size>
          </box>
        </geometry>
      </visual>
      <visual name='base_link_fixed_joint_lump__tray_visual_7'>
        <pose frame=''>0.218 0.2325 0.855 1.5708 -0 1.5708</pose>
        <geometry>
          <mesh>
            <scale>0.001 0.001 0.001</scale>
            <uri>model://cr2/meshes/tray.stl</uri>
          </mesh>
        </geometry>
      </visual>
      <visual name='base_link_fixed_joint_lump__pillar_FRONT_LEFT_link_visual_8'>
        <pose frame=''>0.1825 0.173 0.6 0 -0 0</pose>
        <geometry>
          <cylinder>
            <length>0.02</length>
            <radius>0.006</radius>
          </cylinder>
        </geometry>
      </visual>
      <visual name='base_link_fixed_joint_lump__pillar_FRONT_RIGHT_link_visual_9'>
        <pose frame=''>0.1825 -0.173 0.6 0 -0 0</pose>
        <geometry>
          <cylinder>
            <length>0.02</length>
            <radius>0.006</radius>
          </cylinder>
        </geometry>
      </visual>
      <visual name='base_link_fixed_joint_lump__pillar_REAR_LEFT_link_visual_10'>
        <pose frame=''>-0.1825 0.173 0.6 0 -0 0</pose>
        <geometry>
          <cylinder>
            <length>0.02</length>
            <radius>0.006</radius>
          </cylinder>
        </geometry>
      </visual>
      <visual name='base_link_fixed_joint_lump__pillar_REAR_RIGHT_link_visual_11'>
        <pose frame=''>-0.1825 -0.173 0.6 0 -0 0</pose>
        <geometry>
          <cylinder>
            <length>0.02</length>
            <radius>0.006</radius>
          </cylinder>
        </geometry>
      </visual>
      <velocity_decay/>
      <gravity>1</gravity>
      <gravity>1</gravity>
      <velocity_decay/>
      
    </link>
    <link name='front_left_wheel_link'>
      <pose frame=''>0.16 0.15 0 0 -0 0</pose>
      <inertial>
        <pose frame=''>0 0 0 0 -0 0</pose>
        <mass>2.3</mass>
        <inertia>
          <ixx>0.0033212</ixx>
          <ixy>0</ixy>
          <ixz>0</ixz>
          <iyy>0.0066424</iyy>
          <iyz>0</iyz>
          <izz>0.0033212</izz>
        </inertia>
      </inertial>
      <collision name='front_left_wheel_link_collision'>
        <pose frame=''>0 0 0 1.57075 -0 0</pose>
        <geometry>
          <cylinder>
            <length>0.05</length>
            <radius>0.05</radius>
          </cylinder>
        </geometry>
        <surface>
          <contact>
            <ode>
              <kp>1e+07</kp>
              <kd>1</kd>
            </ode>
          </contact>
          <friction>
            <ode>
              <mu>0</mu>
              <mu2>0</mu2>
            </ode>
          </friction>
        </surface>
      </collision>
      <visual name='front_left_wheel_link_visual'>
        <pose frame=''>0 0 0 1.57075 -0 0</pose>
        <geometry>
          <cylinder>
            <length>0.05</length>
            <radius>0.05</radius>
          </cylinder>
        </geometry>
        <material>
          <script>
            <name>Gazebo/Blue</name>
            <uri>file://media/materials/scripts/gazebo.material</uri>
          </script>
        </material>
      </visual>
      <gravity>1</gravity>
      <velocity_decay/>
    </link>
    <joint name='front_left_wheel' type='revolute'>
      <child>front_left_wheel_link</child>
      <parent>base_link</parent>
      <axis>
        <xyz>0 1 0</xyz>
        <limit>
          <lower>-1e+16</lower>
          <upper>1e+16</upper>
        </limit>
        <dynamics>
          <spring_reference>0</spring_reference>
          <spring_stiffness>0</spring_stiffness>
        </dynamics>
        <use_parent_model_frame>1</use_parent_model_frame>
      </axis>
    </joint>
    <link name='front_right_wheel_link'>
      <pose frame=''>0.16 -0.15 0 0 -0 0</pose>
      <inertial>
        <pose frame=''>0 0 0 0 -0 0</pose>
        <mass>2.3</mass>
        <inertia>
          <ixx>0.0033212</ixx>
          <ixy>0</ixy>
          <ixz>0</ixz>
          <iyy>0.0066424</iyy>
          <iyz>0</iyz>
          <izz>0.0033212</izz>
        </inertia>
      </inertial>
      <collision name='front_right_wheel_link_collision'>
        <pose frame=''>0 0 0 1.57075 -0 0</pose>
        <geometry>
          <cylinder>
            <length>0.05</length>
            <radius>0.05</radius>
          </cylinder>
        </geometry>
        <surface>
          <contact>
            <ode>
              <kp>1e+07</kp>
              <kd>1</kd>
            </ode>
          </contact>
          <friction>
            <ode>
              <mu>0</mu>
              <mu2>0</mu2>
            </ode>
          </friction>
        </surface>
      </collision>
      <visual name='front_right_wheel_link_visual'>
        <pose frame=''>0 0 0 1.57075 -0 0</pose>
        <geometry>
          <cylinder>
            <length>0.05</length>
            <radius>0.05</radius>
          </cylinder>
        </geometry>
        <material>
          <script>
            <name>Gazebo/Blue</name>
            <uri>file://media/materials/scripts/gazebo.material</uri>
          </script>
        </material>
      </visual>
      <gravity>1</gravity>
      <velocity_decay/>
    </link>
    <joint name='front_right_wheel' type='revolute'>
      <child>front_right_wheel_link</child>
      <parent>base_link</parent>
      <axis>
        <xyz>0 1 0</xyz>
        <limit>
          <lower>-1e+16</lower>
          <upper>1e+16</upper>
        </limit>
        <dynamics>
          <spring_reference>0</spring_reference>
          <spring_stiffness>0</spring_stiffness>
        </dynamics>
        <use_parent_model_frame>1</use_parent_model_frame>
      </axis>
    </joint>
    <link name='rear_left_wheel_link'>
      <pose frame=''>-0.14 0.15 0 0 -0 0</pose>
      <inertial>
        <pose frame=''>0 0 0 0 -0 0</pose>
        <mass>2.3</mass>
        <inertia>
          <ixx>0.0033212</ixx>
          <ixy>0</ixy>
          <ixz>0</ixz>
          <iyy>0.0066424</iyy>
          <iyz>0</iyz>
          <izz>0.0033212</izz>
        </inertia>
      </inertial>
      <collision name='rear_left_wheel_link_collision'>
        <pose frame=''>0 0 0 1.57075 -0 0</pose>
        <geometry>
          <cylinder>
            <length>0.05</length>
            <radius>0.05</radius>
          </cylinder>
        </geometry>
        <surface>
          <contact>
            <ode>
              <kp>1e+07</kp>
              <kd>1</kd>
            </ode>
          </contact>
          <friction>
            <ode>
              <mu>0</mu>
              <mu2>0</mu2>
            </ode>
          </friction>
        </surface>
      </collision>
      <visual name='rear_left_wheel_link_visual'>
        <pose frame=''>0 0 0 1.57075 -0 0</pose>
        <geometry>
          <cylinder>
            <length>0.05</length>
            <radius>0.05</radius>
          </cylinder>
        </geometry>
        <material>
          <script>
            <name>Gazebo/Blue</name>
            <uri>file://media/materials/scripts/gazebo.material</uri>
          </script>
        </material>
      </visual>
      <gravity>1</gravity>
      <velocity_decay/>
    </link>
    <joint name='rear_left_wheel' type='revolute'>
      <child>rear_left_wheel_link</child>
      <parent>base_link</parent>
      <axis>
        <xyz>0 1 0</xyz>
        <limit>
          <lower>-1e+16</lower>
          <upper>1e+16</upper>
        </limit>
        <dynamics>
          <spring_reference>0</spring_reference>
          <spring_stiffness>0</spring_stiffness>
        </dynamics>
        <use_parent_model_frame>1</use_parent_model_frame>
      </axis>
    </joint>
    <link name='rear_right_wheel_link'>
      <pose frame=''>-0.14 -0.15 0 0 -0 0</pose>
      <inertial>
        <pose frame=''>0 0 0 0 -0 0</pose>
        <mass>2.3</mass>
        <inertia>
          <ixx>0.0033212</ixx>
          <ixy>0</ixy>
          <ixz>0</ixz>
          <iyy>0.0066424</iyy>
          <iyz>0</iyz>
          <izz>0.0033212</izz>
        </inertia>
      </inertial>
      <collision name='rear_right_wheel_link_collision'>
        <pose frame=''>0 0 0 1.57075 -0 0</pose>
        <geometry>
          <cylinder>
            <length>0.05</length>
            <radius>0.05</radius>
          </cylinder>
        </geometry>
        <surface>
          <contact>
            <ode>
              <kp>1e+07</kp>
              <kd>1</kd>
            </ode>
          </contact>
          <friction>
            <ode>
              <mu>0</mu>
              <mu2>0</mu2>
            </ode>
          </friction>
        </surface>
      </collision>
      <visual name='rear_right_wheel_link_visual'>
        <pose frame=''>0 0 0 1.57075 -0 0</pose>
        <geometry>
          <cylinder>
            <length>0.05</length>
            <radius>0.05</radius>
          </cylinder>
        </geometry>
        <material>
          <script>
            <name>Gazebo/Blue</name>
            <uri>file://media/materials/scripts/gazebo.material</uri>
          </script>
        </material>
      </visual>
      <gravity>1</gravity>
      <velocity_decay/>
    </link>
    <joint name='rear_right_wheel' type='revolute'>
      <child>rear_right_wheel_link</child>
      <parent>base_link</parent>
      <axis>
        <xyz>0 1 0</xyz>
        <limit>
          <lower>-1e+16</lower>
          <upper>1e+16</upper>
        </limit>
        <dynamics>
          <spring_reference>0</spring_reference>
          <spring_stiffness>0</spring_stiffness>
        </dynamics>
        <use_parent_model_frame>1</use_parent_model_frame>
      </axis>
    </joint>

  </model>
</sdf>
