<sdf version='1.6'>
  <model name='cr2'>

    <static>true</static>
    <plugin name="sample" filename="libmove_object_plugin.so" />

    <link name='base_link'>
      <pose frame=''>0 0 0 0 -0 0</pose>
      <inertial>
        <pose frame=''>0.063545 -0.009655 0.290899 1.5708 -0 1.5708</pose>
        <mass>7.967</mass>
        <inertia>
          <ixx>1.23942</ixx>
          <ixy>-0.119632</ixy>
          <ixz>0.13679</ixz>
          <iyy>0.73365</iyy>
          <iyz>-0.015758</iyz>
          <izz>1.18615</izz>
        </inertia>
      </inertial>
      <collision name='base_link_collision'>
        <pose frame=''>0 0 0.1 1.5708 -0 1.5708</pose>
        <geometry>
          <box>
            <size>0.36 0.1 0.4</size>
          </box>
        </geometry>
        <surface>
          <contact>
            <ode/>
          </contact>
          <friction>
            <ode/>
          </friction>
        </surface>
      </collision>
      <collision name='base_link_fixed_joint_lump__body_collision_1'>
        <pose frame=''>0.39 -0.36 0.03 1.5708 -0 -3.14159</pose>
        <geometry>
          <mesh>
            <scale>0.0015 0.0015 0.0015</scale>
            <uri>model://cr2/meshes/body.STL</uri>
          </mesh>
        </geometry>
      </collision>
      <collision name='base_link_fixed_joint_lump__back_cover_collision_2'>
        <pose frame=''>-0.38 0.345 0.03 1.50987 0 -1.5708</pose>
        <geometry>
          <mesh>
            <scale>0.0015 0.0015 0.0015</scale>
            <uri>model://cr2/meshes/back_cover.stl</uri>
          </mesh>
        </geometry>
      </collision>
      <collision name='base_link_fixed_joint_lump__head_collision_3'>
        <pose frame=''>0.347 -0.32 0.055 1.5708 -0 -3.14159</pose>
        <geometry>
          <mesh>
            <scale>0.0015 0.0015 0.0015</scale>
            <uri>model://cr2/meshes/head.STL</uri>
          </mesh>
        </geometry>
      </collision>
      <collision name='base_link_fixed_joint_lump__laser_link_collision_4'>
        <pose frame=''>-0.02 0.005 0.95 3.14159 -0 -3.14159</pose>
        <geometry>
          <cylinder>
            <length>0.041</length>
            <radius>0.038</radius>
          </cylinder>
        </geometry>
      </collision>
      <collision name='base_link_fixed_joint_lump__laser_oscillator_collision_5'>
        <pose frame=''>-0.02 0.005 0.9345 3.14159 -0 -3.14159</pose>
        <geometry>
          <cylinder>
            <length>0.001</length>
            <radius>0.038</radius>
          </cylinder>
        </geometry>
        <surface>
          <contact>
            <ode/>
          </contact>
          <friction>
            <ode/>
          </friction>
        </surface>
      </collision>
      <collision name='base_link_fixed_joint_lump__monitor_collision_6'>
        <pose frame=''>0.327 0.005 1.155 1.5708 -1.45772 -3.14159</pose>
        <geometry>
          <box>
            <size>0.18 0.001 0.27</size>
          </box>
        </geometry>
      </collision>
      <collision name='base_link_fixed_joint_lump__tray_collision_7'>
        <pose frame=''>-0.378 0.345 1.305 1.5708 -0 -3.14159</pose>
        <geometry>
          <mesh>
            <scale>0.0015 0.0015 0.0015</scale>
            <uri>model://cr2/meshes/tray.stl</uri>
          </mesh>
        </geometry>
      </collision>
      <collision name='base_link_fixed_joint_lump__motor_holder_FL_collision_8'>
        <pose frame=''>-0.16 0.1925 0.092 1.5708 -0 0</pose>
        <geometry>
          <cylinder>
            <length>0.025</length>
            <radius>0.02</radius>
          </cylinder>
        </geometry>
      </collision>
      <collision name='base_link_fixed_joint_lump__motor_holder_FR_collision_9'>
        <pose frame=''>-0.16 -0.1925 0.092 1.5708 -0 0</pose>
        <geometry>
          <cylinder>
            <length>0.025</length>
            <radius>0.02</radius>
          </cylinder>
        </geometry>
      </collision>
      <collision name='base_link_fixed_joint_lump__motor_holder_RL_collision_10'>
        <pose frame=''>0.16 0.1925 0.092 1.5708 -0 0</pose>
        <geometry>
          <cylinder>
            <length>0.025</length>
            <radius>0.02</radius>
          </cylinder>
        </geometry>
        <surface>
          <contact>
            <ode>
              <kp>1e+07</kp>
              <kd>1</kd>
            </ode>
          </contact>
          <friction>
            <ode>
              <mu>1</mu>
              <mu2>1</mu2>
            </ode>
          </friction>
        </surface>
      </collision>
      <collision name='base_link_fixed_joint_lump__motor_holder_RR_collision_11'>
        <pose frame=''>0.16 -0.1925 0.092 1.5708 -0 0</pose>
        <geometry>
          <cylinder>
            <length>0.025</length>
            <radius>0.02</radius>
          </cylinder>
        </geometry>
      </collision>
      <visual name='base_link_visual'>
        <pose frame=''>0 0 0.1 1.5708 -0 1.5708</pose>
        <geometry>
          <box>
            <size>0.36 0.1 0.4</size>
          </box>
        </geometry>
        <material>
          <script>
            <name>Gazebo/White</name>
            <uri>file://media/materials/scripts/gazebo.material</uri>
          </script>
        </material>
      </visual>
      <visual name='base_link_fixed_joint_lump__body_visual_1'>
        <pose frame=''>0.39 -0.36 0.03 1.5708 -0 -3.14159</pose>
        <geometry>
          <mesh>
            <scale>0.0015 0.0015 0.0015</scale>
            <uri>model://cr2/meshes/body.STL</uri>
          </mesh>
        </geometry>
      </visual>
      <visual name='base_link_fixed_joint_lump__back_cover_visual_2'>
        <pose frame=''>-0.38 0.345 0.03 1.50987 0 -1.5708</pose>
        <geometry>
          <mesh>
            <scale>0.0015 0.0015 0.0015</scale>
            <uri>model://cr2/meshes/back_cover.stl</uri>
          </mesh>
        </geometry>
      </visual>
      <visual name='base_link_fixed_joint_lump__head_visual_3'>
        <pose frame=''>0.347 -0.32 0.055 1.5708 -0 -3.14159</pose>
        <geometry>
          <mesh>
            <scale>0.0015 0.0015 0.0015</scale>
            <uri>model://cr2/meshes/head.STL</uri>
          </mesh>
        </geometry>
      </visual>
      <visual name='base_link_fixed_joint_lump__laser_link_visual_4'>
        <pose frame=''>-0.02 0.005 0.95 3.14159 -0 -3.14159</pose>
        <geometry>
          <cylinder>
            <length>0.041</length>
            <radius>0.038</radius>
          </cylinder>
        </geometry>
      </visual>
      <visual name='base_link_fixed_joint_lump__laser_oscillator_visual_5'>
        <pose frame=''>-0.02 0.005 0.9345 3.14159 -0 -3.14159</pose>
        <geometry>
          <cylinder>
            <length>0.001</length>
            <radius>0.038</radius>
          </cylinder>
        </geometry>
        <material>
          <script>
            <name>Gazebo/Green</name>
            <uri>file://media/materials/scripts/gazebo.material</uri>
          </script>
        </material>
      </visual>
      <visual name='base_link_fixed_joint_lump__monitor_visual_6'>
        <pose frame=''>0.327 0.005 1.155 1.5708 -1.45772 -3.14159</pose>
        <geometry>
          <box>
            <size>0.18 0.001 0.27</size>
          </box>
        </geometry>
      </visual>
      <visual name='base_link_fixed_joint_lump__tray_visual_7'>
        <pose frame=''>-0.378 0.345 1.305 1.5708 -0 -3.14159</pose>
        <geometry>
          <mesh>
            <scale>0.0015 0.0015 0.0015</scale>
            <uri>model://cr2/meshes/tray.stl</uri>
          </mesh>
        </geometry>
      </visual>
      <visual name='base_link_fixed_joint_lump__motor_holder_FL_visual_8'>
        <pose frame=''>-0.16 0.1925 0.092 1.5708 -0 0</pose>
        <geometry>
          <cylinder>
            <length>0.025</length>
            <radius>0.02</radius>
          </cylinder>
        </geometry>
      </visual>
      <visual name='base_link_fixed_joint_lump__motor_holder_FR_visual_9'>
        <pose frame=''>-0.16 -0.1925 0.092 1.5708 -0 0</pose>
        <geometry>
          <cylinder>
            <length>0.025</length>
            <radius>0.02</radius>
          </cylinder>
        </geometry>
      </visual>
      <visual name='base_link_fixed_joint_lump__motor_holder_RL_visual_10'>
        <pose frame=''>0.16 0.1925 0.092 1.5708 -0 0</pose>
        <geometry>
          <cylinder>
            <length>0.025</length>
            <radius>0.02</radius>
          </cylinder>
        </geometry>
        <material>
          <script>
            <name>Gazebo/Red</name>
            <uri>file://media/materials/scripts/gazebo.material</uri>
          </script>
        </material>
      </visual>
      <visual name='base_link_fixed_joint_lump__motor_holder_RR_visual_11'>
        <pose frame=''>0.16 -0.1925 0.092 1.5708 -0 0</pose>
        <geometry>
          <cylinder>
            <length>0.025</length>
            <radius>0.02</radius>
          </cylinder>
        </geometry>
      </visual>
      <velocity_decay/>
      <gravity>1</gravity>
      <velocity_decay/>
      <sensor name='laser' type='ray'>
        <visualize>0</visualize>
        <update_rate>40</update_rate>
        <ray>
          <scan>
            <horizontal>
              <samples>1081</samples>
              <resolution>1</resolution>
              <min_angle>0</min_angle>
              <max_angle>6.28318</max_angle>
            </horizontal>
          </scan>
          <range>
            <min>0.15</min>
            <max>3</max>
            <resolution>0.01</resolution>
          </range>
          <noise>
            <type>gaussian</type>
            <mean>0</mean>
            <stddev>0.01</stddev>
          </noise>
        </ray>
        <plugin name='gazebo_ros_rplidar_controller' filename='libgazebo_ros_laser.so'>
          <topicName>front/scan</topicName>
          <frameName>laser_oscillator</frameName>
        </plugin>
        <pose frame=''>-0.02 0.005 0.9345 3.14159 -0 -3.14159</pose>
      </sensor>
      <gravity>1</gravity>
      <velocity_decay/>
      <self_collide>0</self_collide>
    </link>
    <link name='wheel_FL_link'>
      <pose frame=''>-0.16 0.23 0.092 1.5708 -0 0</pose>
      <inertial>
        <pose frame=''>0 0 0 0 -0 0</pose>
        <mass>0.1</mass>
        <inertia>
          <ixx>0.000333333</ixx>
          <ixy>0</ixy>
          <ixz>0</ixz>
          <iyy>0.000333333</iyy>
          <iyz>0</iyz>
          <izz>0.0005</izz>
        </inertia>
      </inertial>
      <collision name='wheel_FL_link_collision'>
        <pose frame=''>0 0 0 0 -0 0</pose>
        <geometry>
          <cylinder>
            <length>0.1</length>
            <radius>0.1</radius>
          </cylinder>
        </geometry>
        <surface>
          <contact>
            <ode>
              <kp>1e+07</kp>
              <kd>1</kd>
            </ode>
          </contact>
          <friction>
            <ode>
              <mu>0</mu>
              <mu2>0</mu2>
            </ode>
          </friction>
        </surface>
      </collision>
      <visual name='wheel_FL_link_visual'>
        <pose frame=''>0 0 0 0 -0 0</pose>
        <geometry>
          <cylinder>
            <length>0.1</length>
            <radius>0.1</radius>
          </cylinder>
        </geometry>
        <material>
          <script>
            <name>Gazebo/Blue</name>
            <uri>file://media/materials/scripts/gazebo.material</uri>
          </script>
        </material>
      </visual>
      <gravity>1</gravity>
      <velocity_decay/>
      <self_collide>0</self_collide>
    </link>
    <joint name='wheel_motor_FL_joint' type='revolute'>
      <child>wheel_FL_link</child>
      <parent>base_link</parent>
      <axis>
        <xyz>0 -1 0</xyz>
        <limit>
          <lower>-1e+16</lower>
          <upper>1e+16</upper>
        </limit>
        <dynamics>
          <spring_reference>0</spring_reference>
          <spring_stiffness>0</spring_stiffness>
        </dynamics>
        <use_parent_model_frame>1</use_parent_model_frame>
      </axis>
    </joint>
    <link name='wheel_FR_link'>
      <pose frame=''>-0.16 -0.23 0.092 1.5708 -0 0</pose>
      <inertial>
        <pose frame=''>0 0 0 0 -0 0</pose>
        <mass>0.1</mass>
        <inertia>
          <ixx>0.000333333</ixx>
          <ixy>0</ixy>
          <ixz>0</ixz>
          <iyy>0.000333333</iyy>
          <iyz>0</iyz>
          <izz>0.0005</izz>
        </inertia>
      </inertial>
      <collision name='wheel_FR_link_collision'>
        <pose frame=''>0 0 0 0 -0 0</pose>
        <geometry>
          <cylinder>
            <length>0.1</length>
            <radius>0.1</radius>
          </cylinder>
        </geometry>
        <surface>
          <contact>
            <ode>
              <kp>1e+07</kp>
              <kd>1</kd>
            </ode>
          </contact>
          <friction>
            <ode>
              <mu>0</mu>
              <mu2>0</mu2>
            </ode>
          </friction>
        </surface>
      </collision>
      <visual name='wheel_FR_link_visual'>
        <pose frame=''>0 0 0 0 -0 0</pose>
        <geometry>
          <cylinder>
            <length>0.1</length>
            <radius>0.1</radius>
          </cylinder>
        </geometry>
        <material>
          <script>
            <name>Gazebo/Blue</name>
            <uri>file://media/materials/scripts/gazebo.material</uri>
          </script>
        </material>
      </visual>
      <gravity>1</gravity>
      <velocity_decay/>
      <self_collide>0</self_collide>
    </link>
    <joint name='wheel_motor_FR_joint' type='revolute'>
      <child>wheel_FR_link</child>
      <parent>base_link</parent>
      <axis>
        <xyz>0 -1 0</xyz>
        <limit>
          <lower>-1e+16</lower>
          <upper>1e+16</upper>
        </limit>
        <dynamics>
          <spring_reference>0</spring_reference>
          <spring_stiffness>0</spring_stiffness>
        </dynamics>
        <use_parent_model_frame>1</use_parent_model_frame>
      </axis>
    </joint>
    <link name='wheel_RL_link'>
      <pose frame=''>0.16 0.23 0.092 1.5708 -0 0</pose>
      <inertial>
        <pose frame=''>0 0 0 0 -0 0</pose>
        <mass>0.1</mass>
        <inertia>
          <ixx>0.000333333</ixx>
          <ixy>0</ixy>
          <ixz>0</ixz>
          <iyy>0.000333333</iyy>
          <iyz>0</iyz>
          <izz>0.0005</izz>
        </inertia>
      </inertial>
      <collision name='wheel_RL_link_collision'>
        <pose frame=''>0 0 0 0 -0 0</pose>
        <geometry>
          <cylinder>
            <length>0.1</length>
            <radius>0.1</radius>
          </cylinder>
        </geometry>
        <surface>
          <contact>
            <ode>
              <kp>1e+07</kp>
              <kd>1</kd>
            </ode>
          </contact>
          <friction>
            <ode>
              <mu>0</mu>
              <mu2>0</mu2>
            </ode>
          </friction>
        </surface>
      </collision>
      <visual name='wheel_RL_link_visual'>
        <pose frame=''>0 0 0 0 -0 0</pose>
        <geometry>
          <cylinder>
            <length>0.1</length>
            <radius>0.1</radius>
          </cylinder>
        </geometry>
        <material>
          <script>
            <name>Gazebo/Blue</name>
            <uri>file://media/materials/scripts/gazebo.material</uri>
          </script>
        </material>
      </visual>
      <gravity>1</gravity>
      <velocity_decay/>
      <self_collide>0</self_collide>
    </link>
    <joint name='wheel_motor_RL_joint' type='revolute'>
      <child>wheel_RL_link</child>
      <parent>base_link</parent>
      <axis>
        <xyz>0 -1 0</xyz>
        <limit>
          <lower>-1e+16</lower>
          <upper>1e+16</upper>
        </limit>
        <dynamics>
          <spring_reference>0</spring_reference>
          <spring_stiffness>0</spring_stiffness>
        </dynamics>
        <use_parent_model_frame>1</use_parent_model_frame>
      </axis>
      <physics>
        <ode>
          <limit>
            <cfm>0</cfm>
            <erp>0.2</erp>
          </limit>
        </ode>
      </physics>
    </joint>
    <link name='wheel_RR_link'>
      <pose frame=''>0.16 -0.23 0.092 1.5708 -0 0</pose>
      <inertial>
        <pose frame=''>0 0 0 0 -0 0</pose>
        <mass>0.1</mass>
        <inertia>
          <ixx>0.000333333</ixx>
          <ixy>0</ixy>
          <ixz>0</ixz>
          <iyy>0.000333333</iyy>
          <iyz>0</iyz>
          <izz>0.0005</izz>
        </inertia>
      </inertial>
      <collision name='wheel_RR_link_collision'>
        <pose frame=''>0 0 0 0 -0 0</pose>
        <geometry>
          <cylinder>
            <length>0.1</length>
            <radius>0.1</radius>
          </cylinder>
        </geometry>
        <surface>
          <contact>
            <ode>
              <kp>1e+07</kp>
              <kd>1</kd>
            </ode>
          </contact>
          <friction>
            <ode>
              <mu>0</mu>
              <mu2>0</mu2>
            </ode>
          </friction>
        </surface>
      </collision>
      <visual name='wheel_RR_link_visual'>
        <pose frame=''>0 0 0 0 -0 0</pose>
        <geometry>
          <cylinder>
            <length>0.1</length>
            <radius>0.1</radius>
          </cylinder>
        </geometry>
        <material>
          <script>
            <name>Gazebo/Blue</name>
            <uri>file://media/materials/scripts/gazebo.material</uri>
          </script>
        </material>
      </visual>
      <gravity>1</gravity>
      <velocity_decay/>
      <self_collide>0</self_collide>
    </link>
    <joint name='wheel_motor_RR_joint' type='revolute'>
      <child>wheel_RR_link</child>
      <parent>base_link</parent>
      <axis>
        <xyz>0 -1 0</xyz>
        <limit>
          <lower>-1e+16</lower>
          <upper>1e+16</upper>
        </limit>
        <dynamics>
          <spring_reference>0</spring_reference>
          <spring_stiffness>0</spring_stiffness>
        </dynamics>
        <use_parent_model_frame>1</use_parent_model_frame>
      </axis>
    </joint>
    <static>0</static>
    <plugin name='gazebo_ros_control' filename='libgazebo_ros_control.so'>
      <robotNamespace>/</robotNamespace>
    </plugin>
    <plugin name='ridgeback_ros_force_based_move' filename='libridgeback_ros_force_based_move.so'>
      <robotNamespace>/</robotNamespace>
      <commandTopic>cmd_vel</commandTopic>
      <odometryTopic>odom</odometryTopic>
      <odometryFrame>odom</odometryFrame>
      <odometryRate>25.0</odometryRate>
      <robotBaseFrame>base_link</robotBaseFrame>
      <cmdVelTimeOut>0.25</cmdVelTimeOut>
      <publishOdometryTf>0</publishOdometryTf>
      <yaw_velocity_p_gain>500.0</yaw_velocity_p_gain>
      <x_velocity_p_gain>10000.0</x_velocity_p_gain>
      <y_velocity_p_gain>10000.0</y_velocity_p_gain>
    </plugin>
  </model>
</sdf>
