<?xml version="1.0" ?>
<!-- =================================================================================== -->
<!-- |    This document was autogenerated by xacro from cr2.urdf.xacro                 | -->
<!-- |    EDITING THIS FILE BY HAND IS NOT RECOMMENDED                                 | -->
<!-- =================================================================================== -->
<robot name="cr2" xmlns:xacro="http://ros.org/wiki/xacro">
  <!-- weight of iPad mini 4 -->
  <!-- For performance purposes we temporary remove real geometry of wheels and put simple cylinders -->
  <link name="base_link">
    <visual>
      <origin rpy="1.57079632679 0 1.57079632679" xyz="0 0 0.1"/>
      <geometry>
        <box size="0.36 0.1 0.4"/>
      </geometry>
      <material name="navajo_white">
        <color rgba="1.0 0.87 0.68 1.0"/>
      </material>
    </visual>
    <collision>
      <origin rpy="1.57079632679 0 1.57079632679" xyz="0 0 0.1"/>
      <geometry>
        <box size="0.36 0.1 0.4"/>
      </geometry>
    </collision>
    <inertial>
      <origin rpy="1.57079632679 0 1.57079632679" xyz="0 0 0.1"/>
      <mass value="3"/>
      <inertia ixx="0.0425" ixy="0.0" ixz="0.0" iyy="0.0724" iyz="0.0" izz="0.0349"/>
    </inertial>
  </link>
  <link name="motor_holder_RL">
    <visual>
      <geometry>
        <cylinder length="0.025" radius="0.02"/>
      </geometry>
      <material name="blue">
        <color rgba="0.0 0.0 1.0 1.0"/>
      </material>
    </visual>
    <collision>
      <geometry>
        <cylinder length="0.025" radius="0.02"/>
      </geometry>
    </collision>
    <inertial>
      <mass value="0.088"/>
      <origin xyz="0 0 0"/>
      <inertia ixx="1.33833333333e-05" ixy="0.0" ixz="0.0" iyy="1.33833333333e-05" iyz="0.0" izz="1.76e-05"/>
    </inertial>
  </link>
  <joint name="motor_holder_base_RL_joint" type="fixed">
    <origin rpy="1.57079632679 0 0" xyz="0.16 0.1925 0.092"/>
    <parent link="base_link"/>
    <child link="motor_holder_RL"/>
  </joint>
  <link name="wheel_RL_link">
    <visual>
      <geometry>
        <cylinder length="0.1" radius="0.1"/>
      </geometry>
    </visual>
    <collision>
      <geometry>
        <cylinder length="0.1" radius="0.1"/>
      </geometry>
    </collision>
    <inertial>
      <mass value="0.1"/>
      <origin xyz="0 0 0"/>
      <inertia ixx="0.000333333333333" ixy="0.0" ixz="0.0" iyy="0.000333333333333" iyz="0.0" izz="0.0005"/>
    </inertial>
  </link>
  <joint name="wheel_motor_RL_joint" type="continuous">
    <origin rpy="0 0 0" xyz="0 0 -0.0375"/>
    <parent link="motor_holder_RL"/>
    <child link="wheel_RL_link"/>
    <axis xyz="0 0 1"/>
  </joint>
  <transmission name="wheel_transmission_RL">
    <type>transmission_interface/SimpleTransmission</type>
    <joint name="wheel_motor_RL_joint">
      <hardwareInterface>hardware_interface/VelocityJointInterface</hardwareInterface>
    </joint>
    <actuator name="wheel_motor_RL">
      <hardwareInterface>hardware_interface/VelocityJointInterface</hardwareInterface>
      <mechanicalReduction>131</mechanicalReduction>
      <motorTorqueConstant>4.4</motorTorqueConstant>
    </actuator>
  </transmission>
  <link name="motor_holder_RR">
            
    <visual>
      <geometry>
        <cylinder length="0.025" radius="0.02"/>
      </geometry>
      <material name="blue">
        <color rgba="0.0 0.0 1.0 1.0"/>
      </material>
    </visual>
    <collision>
      <geometry>
        <cylinder length="0.025" radius="0.02"/>
      </geometry>
    </collision>
    <inertial>
      <mass value="0.088"/>
      <origin xyz="0 0 0"/>
      <inertia ixx="1.33833333333e-05" ixy="0.0" ixz="0.0" iyy="1.33833333333e-05" iyz="0.0" izz="1.76e-05"/>
    </inertial>
  </link>
  <joint name="motor_holder_base_RR_joint" type="fixed">
    <origin rpy="1.57079632679 0 0" xyz="0.16 -0.1925 0.092"/>
    <parent link="base_link"/>
    <child link="motor_holder_RR"/>
  </joint>
  <link name="wheel_RR_link">
    <visual>
      <geometry>
        <cylinder length="0.1" radius="0.1"/>
      </geometry>
    </visual>
    <collision>
      <geometry>
        <cylinder length="0.1" radius="0.1"/>
      </geometry>
    </collision>
    <inertial>
      <mass value="0.1"/>
      <origin xyz="0 0 0"/>
      <inertia ixx="0.000333333333333" ixy="0.0" ixz="0.0" iyy="0.000333333333333" iyz="0.0" izz="0.0005"/>
    </inertial>
  </link>
  <joint name="wheel_motor_RR_joint" type="continuous">
    <origin rpy="0 0 0" xyz="0 0 0.0375"/>
    <parent link="motor_holder_RR"/>
    <child link="wheel_RR_link"/>
    <axis xyz="0 0 1"/>
  </joint>
  <transmission name="wheel_transmission_RR">
    <type>transmission_interface/SimpleTransmission</type>
    <joint name="wheel_motor_RR_joint">
      <hardwareInterface>hardware_interface/VelocityJointInterface</hardwareInterface>
    </joint>
    <actuator name="wheel_motor_RR">
      <hardwareInterface>hardware_interface/VelocityJointInterface</hardwareInterface>
      <mechanicalReduction>131</mechanicalReduction>
      <motorTorqueConstant>4.4</motorTorqueConstant>
    </actuator>
  </transmission>
  <link name="motor_holder_FL">
            
    <visual>
      <geometry>
        <cylinder length="0.025" radius="0.02"/>
      </geometry>
      <material name="blue">
        <color rgba="0.0 0.0 1.0 1.0"/>
      </material>
    </visual>
    <collision>
      <geometry>
        <cylinder length="0.025" radius="0.02"/>
      </geometry>
    </collision>
    <inertial>
      <mass value="0.088"/>
      <origin xyz="0 0 0"/>
      <inertia ixx="1.33833333333e-05" ixy="0.0" ixz="0.0" iyy="1.33833333333e-05" iyz="0.0" izz="1.76e-05"/>
    </inertial>
  </link>
  <joint name="motor_holder_base_FL_joint" type="fixed">
    <origin rpy="1.57079632679 0 0" xyz="-0.16 0.1925 0.092"/>
    <parent link="base_link"/>
    <child link="motor_holder_FL"/>
  </joint>
  <link name="wheel_FL_link">
    <visual>
      <geometry>
        <cylinder length="0.1" radius="0.1"/>
      </geometry>
    </visual>
    <collision>
      <geometry>
        <cylinder length="0.1" radius="0.1"/>
      </geometry>
    </collision>
    <inertial>
      <mass value="0.1"/>
      <origin xyz="0 0 0"/>
      <inertia ixx="0.000333333333333" ixy="0.0" ixz="0.0" iyy="0.000333333333333" iyz="0.0" izz="0.0005"/>
    </inertial>
  </link>
  <joint name="wheel_motor_FL_joint" type="continuous">
    <origin rpy="0 0 0" xyz="0 0 -0.0375"/>
    <parent link="motor_holder_FL"/>
    <child link="wheel_FL_link"/>
    <axis xyz="0 0 1"/>
  </joint>
  <transmission name="wheel_transmission_FL">
    <type>transmission_interface/SimpleTransmission</type>
    <joint name="wheel_motor_FL_joint">
      <hardwareInterface>hardware_interface/VelocityJointInterface</hardwareInterface>
    </joint>
    <actuator name="wheel_motor_FL">
      <hardwareInterface>hardware_interface/VelocityJointInterface</hardwareInterface>
      <mechanicalReduction>131</mechanicalReduction>
      <motorTorqueConstant>4.4</motorTorqueConstant>
    </actuator>
  </transmission>
  <link name="motor_holder_FR">
    &gt;
            
    <visual>
      <geometry>
        <cylinder length="0.025" radius="0.02"/>
      </geometry>
      <material name="blue">
        <color rgba="0.0 0.0 1.0 1.0"/>
      </material>
    </visual>
    <collision>
      <geometry>
        <cylinder length="0.025" radius="0.02"/>
      </geometry>
    </collision>
    <inertial>
      <mass value="0.088"/>
      <origin xyz="0 0 0"/>
      <inertia ixx="1.33833333333e-05" ixy="0.0" ixz="0.0" iyy="1.33833333333e-05" iyz="0.0" izz="1.76e-05"/>
    </inertial>
  </link>
  <joint name="motor_holder_base_FR_joint" type="fixed">
    <origin rpy="1.57079632679 0 0" xyz="-0.16 -0.1925 0.092"/>
    <parent link="base_link"/>
    <child link="motor_holder_FR"/>
  </joint>
  <link name="wheel_FR_link">
    <visual>
      <geometry>
        <cylinder length="0.1" radius="0.1"/>
      </geometry>
    </visual>
    <collision>
      <geometry>
        <cylinder length="0.1" radius="0.1"/>
      </geometry>
    </collision>
    <inertial>
      <mass value="0.1"/>
      <origin xyz="0 0 0"/>
      <inertia ixx="0.000333333333333" ixy="0.0" ixz="0.0" iyy="0.000333333333333" iyz="0.0" izz="0.0005"/>
    </inertial>
  </link>
  <joint name="wheel_motor_FR_joint" type="continuous">
    <origin rpy="0 0 0" xyz="0 0 0.0375"/>
    <parent link="motor_holder_FR"/>
    <child link="wheel_FR_link"/>
    <axis xyz="0 0 1"/>
  </joint>
  <transmission name="wheel_transmission_FR">
    <type>transmission_interface/SimpleTransmission</type>
    <joint name="wheel_motor_FR_joint">
      <hardwareInterface>hardware_interface/VelocityJointInterface</hardwareInterface>
    </joint>
    <actuator name="wheel_motor_FR">
      <hardwareInterface>hardware_interface/VelocityJointInterface</hardwareInterface>
      <mechanicalReduction>131</mechanicalReduction>
      <motorTorqueConstant>4.4</motorTorqueConstant>
    </actuator>
  </transmission>
  <joint name="body_link_joint" type="fixed">
    <origin rpy="1.57079632679 0 3.14159265359" xyz="0.39 -0.36 0.03"/>
    <parent link="base_link"/>
    <child link="body"/>
  </joint>
  <link name="body">
    <visual>
      <origin rpy="0 0 0" xyz="0 0 0"/>
      <geometry>
        <mesh filename="package://cr2_description/meshes/body.STL" scale="0.0015 0.0015 0.0015"/>
      </geometry>
      <material name="red">
        <color rgba="1.0 0.0 0.0 1.0"/>
      </material>
    </visual>
    <collision>
      <origin rpy="0 0 0" xyz="0 0 0"/>
      <geometry>
        <mesh filename="package://cr2_description/meshes/body.STL" scale="0.0015 0.0015 0.0015"/>
      </geometry>
    </collision>
    <inertial>
      <origin rpy="0 1.57079632679 0" xyz="0.331 0.448 0.406"/>
      <mass value="3"/>
      <inertia ixx="0.34208" ixy="0.0" ixz="0.0" iyy="0.250937" iyz="0.0" izz="0.310265"/>
    </inertial>
  </link>
  <link name="back_cover">
    <visual>
      <origin rpy="0 0 0" xyz="0 0 0"/>
      <geometry>
        <mesh filename="package://cr2_description/meshes/back_cover.stl" scale="0.0015 0.0015 0.0015"/>
      </geometry>
      <material name="red">
        <color rgba="1.0 0.0 0.0 1.0"/>
      </material>
    </visual>
    <collision>
      <origin rpy="0 0 0" xyz="0 0 0"/>
      <geometry>
        <mesh filename="package://cr2_description/meshes/back_cover.stl" scale="0.0015 0.0015 0.0015"/>
      </geometry>
    </collision>
    <inertial>
      <origin rpy="0 0 0" xyz="0 0 0"/>
      <mass value="0.2"/>
      <inertia ixx="0.0" ixy="0.0" ixz="0.0" iyy="0.0" iyz="0.0" izz="0.0"/>
    </inertial>
  </link>
  <joint name="back_cover_joint" type="fixed">
    <origin rpy="0 1.57079632679 0.06092665" xyz="0.77 0 0.705"/>
    <parent link="body"/>
    <child link="back_cover"/>
  </joint>
  <link name="head">
    <visual>
      <origin rpy="0 0 0" xyz="0 0 0"/>
      <geometry>
        <mesh filename="package://cr2_description/meshes/head.STL" scale="0.0015 0.0015 0.0015"/>
      </geometry>
      <material name="green">
        <color rgba="0.0 1.0 0.0 1.0"/>
      </material>
    </visual>
    <collision>
      <origin rpy="0 0 0" xyz="0 0 0"/>
      <geometry>
        <mesh filename="package://cr2_description/meshes/head.STL" scale="0.0015 0.0015 0.0015"/>
      </geometry>
    </collision>
    <inertial>
      <origin rpy="0 0 0" xyz="0 0 0"/>
      <mass value="1"/>
      <inertia ixx="0.0505788333333" ixy="0.0" ixz="0.0" iyy="0.0659055" iyz="0.0" izz="0.0405468333333"/>
    </inertial>
  </link>
  <joint name="head_link_joint" type="fixed">
    <origin rpy="0 0 0" xyz="0.043 0.025 0.04"/>
    <parent link="body"/>
    <child link="head"/>
  </joint>
  <link name="tray">
    <visual>
      <origin rpy="0 0 0" xyz="0 0 0"/>
      <geometry>
        <mesh filename="package://cr2_description/meshes/tray.stl" scale="0.0015 0.0015 0.0015"/>
      </geometry>
      <material name="green">
        <color rgba="0.0 1.0 0.0 1.0"/>
      </material>
    </visual>
    <collision>
      <origin rpy="0 0 0" xyz="0 0 0"/>
      <geometry>
        <mesh filename="package://cr2_description/meshes/tray.stl" scale="0.0015 0.0015 0.0015"/>
      </geometry>
    </collision>
    <inertial>
      <origin rpy="0 0 0" xyz="0 0 0"/>
      <mass value="0.1"/>
      <inertia ixx="0.00168750833333" ixy="0.0" ixz="0.0" iyy="0.00336001666667" iyz="0.0" izz="0.00168750833333"/>
    </inertial>
  </link>
  <joint name="tray_joint" type="fixed">
    <origin rpy="0 0 0" xyz="0.725 1.25 0.665"/>
    <parent link="head"/>
    <child link="tray"/>
  </joint>
  <link name="monitor">
    <visual>
      <origin rpy="0 0 0" xyz="0 0 0"/>
      <geometry>
        <box size="0.18 0.001 0.27"/>
      </geometry>
      <material name="black">
        <color rgba="0.0 0.0 0.0 1.0"/>
      </material>
    </visual>
    <collision>
      <origin rpy="0 0 0" xyz="0 0 0"/>
      <geometry>
        <box size="0.18 0.001 0.27"/>
      </geometry>
    </collision>
    <inertial>
      <origin rpy="0 0 0" xyz="0 0 0"/>
      <mass value="0.295"/>
      <inertia ixx="0.00179214958333" ixy="0.0" ixz="0.0" iyy="0.002588625" iyz="0.0" izz="0.000796524583333"/>
    </inertial>
  </link>
  <joint name="monitor_joint" type="fixed">
    <origin rpy="0 0 1.45772297679" xyz="0.02 1.1 0.325"/>
    <parent link="head"/>
    <child link="monitor"/>
  </joint>
  <!--<xacro:pillar parent_link_name="body" position="FRONT_RIGHT" x="0.13" y="0.9032" z="0.12"/>-->
  <!--<xacro:pillar parent_link_name="body" position="RIGHT_SIDE" x="0.68"  y="0.9032" z="0.12"/>-->
  <!--<xacro:pillar parent_link_name="body" position="SIDE_LEFT"  x="0.68"     y="0.9032" z="0.61"/>-->
  <!--<xacro:pillar parent_link_name="body" position="LEFT_FRONT" x="0.13"     y="0.9032" z="0.61"/>-->
  <link name="laser_link">
    <visual>
      <geometry>
        <cylinder length="0.041" radius="0.038"/>
      </geometry>
      <material name="navajo_white">
        <color rgba="1.0 0.87 0.68 1.0"/>
      </material>
    </visual>
    <collision>
      <geometry>
        <cylinder length="0.041" radius="0.038"/>
      </geometry>
    </collision>
    <inertial>
      <mass value="0.019"/>
      <origin xyz="0 0 0"/>
      <inertia ixx="9.52058333333e-06" ixy="0.0" ixz="0.0" iyy="9.52058333333e-06" iyz="0.0" izz="1.3718e-05"/>
    </inertial>
  </link>
  <joint name="laser_base_joint" type="fixed">
    <origin rpy="1.57079632679 0 0" xyz="0.367 0.895 0.325"/>
    <parent link="head"/>
    <child link="laser_link"/>
  </joint>
  <link name="laser_oscillator">
    <visual>
      <geometry>
        <cylinder length="0.001" radius="0.038"/>
      </geometry>
      <material name="blue">
        <color rgba="0.0 0.0 1.0 1.0"/>
      </material>
    </visual>
    <collision>
      <geometry>
        <cylinder length="0.001" radius="0.038"/>
      </geometry>
    </collision>
    <inertial>
      <mass value="0.001"/>
      <origin xyz="0 0 0"/>
      <inertia ixx="3.61083333333e-07" ixy="0.0" ixz="0.0" iyy="3.61083333333e-07" iyz="0.0" izz="7.22e-07"/>
    </inertial>
  </link>
  <joint name="laser_oscillator_joint" type="fixed">
    <origin rpy="0 0 0" xyz="0 0 0.0155"/>
    <parent link="laser_link"/>
    <child link="laser_oscillator"/>
  </joint>
  <gazebo reference="laser_oscillator">
    <material>Gazebo/Green</material>
    <sensor name="laser" type="ray">
      <pose>0 0 0 0 0 0</pose>
      <visualize>false</visualize>
      <update_rate>40</update_rate>
      <ray>
        <scan>
          <horizontal>
            <!--TODO: figureout exact samples for RPLIDAR A2-->
            <samples>1081</samples>
            <resolution>1</resolution>
            <min_angle>0</min_angle>
            <max_angle>6.283185</max_angle>
          </horizontal>
        </scan>
        <range>
          <!--TODO: figureout exact min/max for RPLIDAR A2-->
          <min>0.15</min>
          <max>3.0</max>
          <!--for this dist is configured navigator-->
          <resolution>0.01</resolution>
        </range>
        <noise>
          <type>gaussian</type>
          <mean>0.0</mean>
          <stddev>0.01</stddev>
        </noise>
      </ray>
      <plugin filename="libgazebo_ros_laser.so" name="gazebo_ros_rplidar_controller">
        <!--<topicName>laser/scan</topicName>-->
        <topicName>front/scan</topicName>
        <frameName>laser_oscillator</frameName>
        <!--<frameName>front_laser</frameName>-->
      </plugin>
    </sensor>
  </gazebo>
  <!---->
  <!---->
  <!---->
  <!--ULTRASONIC-->
  <!--<xacro:ultrasonic parent_link_name="body" position="FRONT_TOP"              roll="0"              x="0.1"   y="${ultrasonic_top_margin}            " z="0.361"/>-->
  <!--<xacro:ultrasonic parent_link_name="body" position="FRONT_BOTTOM"           roll="0"              x="0.025" y="${ultrasonic_bottom_margin}         " z="0.361"/>-->
  <!--<xacro:ultrasonic parent_link_name="body" position="FRONT_BOTTOM_RIGHT"     roll="${pi + pi/1.3}" x="0.033" y="${ultrasonic_bottom_margin - 0.003} " z="0.054"/>-->
  <!--<xacro:ultrasonic parent_link_name="body" position="FRONT_BOTTOM_LEFT"      roll="${pi/4}"        x="0.035" y="${ultrasonic_bottom_margin}         " z="0.67" />-->
  <!--<xacro:ultrasonic parent_link_name="body" position="RIGHT_TOP"              roll="${pi + pi/2}"   x="0.374" y="${ultrasonic_top_margin}            " z="0.075"/>-->
  <!--<xacro:ultrasonic parent_link_name="body" position="RIGHT_BOTTOM"           roll="${pi + pi/2}"   x="0.407" y="${ultrasonic_bottom_margin  - 0.002}" z="0.035"/>-->
  <!--<xacro:ultrasonic parent_link_name="body" position="RIGHT_BOTTOM_SIDE"      roll="${pi/1.3}"      x="0.735" y="${ultrasonic_bottom_margin - 0.002} " z="0.675"/>-->
  <!--<xacro:ultrasonic parent_link_name="body" position="SIDE_TOP"               roll="${pi}"          x="0.71"  y="${ultrasonic_top_margin + 0.012}    " z="0.36" />-->
  <!--<xacro:ultrasonic parent_link_name="body" position="SIDE_BOTTOM"            roll="${pi}"          x="0.75"  y="${ultrasonic_bottom_margin}         " z="0.363"/>-->
  <!--<xacro:ultrasonic parent_link_name="body" position="SIDE_BOTTOM_LEFT"       roll="${pi + pi/4}"   x="0.732" y="${ultrasonic_bottom_margin + 0.006} " z="0.055"/>-->
  <!--<xacro:ultrasonic parent_link_name="body" position="LEFT_TOP"               roll="${pi/2}"        x="0.372" y="${ultrasonic_top_margin}            " z="0.65" />-->
  <!--<xacro:ultrasonic parent_link_name="body" position="LEFT_BOTTOM"            roll="${pi/2}"        x="0.407" y="${ultrasonic_bottom_margin}         " z="0.685"/>-->
  <!---->
  <!---->
  <!---->
  <!--RANGE SENSOR-->
  <!--<xacro:range_sensor parent_link_name="head" position="FRONT_FIRST"          roll="0"              x="0.13"  y="${range_sensor_margin}         " z="0.5"/>-->
  <!--<xacro:range_sensor parent_link_name="head" position="FRONT_SECOND"         roll="0"              x="0.13"  y="${range_sensor_margin}         " z="0.325"/>-->
  <!--<xacro:range_sensor parent_link_name="head" position="FRONT_THIRD"          roll="0"              x="0.13"  y="${range_sensor_margin}         " z="0.15"/>-->
  <!--<xacro:range_sensor parent_link_name="head" position="RIGHT_FIRST"          roll="${pi/2}"        x="0.2"   y="${range_sensor_margin}         " z="0.075"/>-->
  <!--<xacro:range_sensor parent_link_name="head" position="RIGHT_SECOND"         roll="${pi/2}"        x="0.38"  y="${range_sensor_margin}         " z="0.075"/>-->
  <!--<xacro:range_sensor parent_link_name="head" position="RIGHT_THIRD"          roll="${pi/2}"        x="0.55"  y="${range_sensor_margin}         " z="0.075"/>-->
  <!--<xacro:range_sensor parent_link_name="head" position="SIDE_FIRST"           roll="0"              x="0.63"  y="${range_sensor_margin}         " z="0.5"/>-->
  <!--<xacro:range_sensor parent_link_name="head" position="SIDE_SECOND"          roll="0"              x="0.63"  y="${range_sensor_margin}         " z="0.325"/>-->
  <!--<xacro:range_sensor parent_link_name="head" position="SIDE_THIRD"           roll="0"              x="0.63"  y="${range_sensor_margin}         " z="0.15"/>-->
  <!--<xacro:range_sensor parent_link_name="head" position="LEFT_FIRST"           roll="${pi/2}"        x="0.2"   y="${range_sensor_margin}         " z="0.572"/>-->
  <!--<xacro:range_sensor parent_link_name="head" position="LEFT_SECOND"          roll="${pi/2}"        x="0.36"  y="${range_sensor_margin}         " z="0.572"/>-->
  <!--<xacro:range_sensor parent_link_name="head" position="LEFT_THIRD"           roll="${pi/2}"        x="0.55"  y="${range_sensor_margin}         " z="0.572"/>-->
  <!---->
  <!---->
  <gazebo>
    <plugin filename="libgazebo_ros_control.so" name="gazebo_ros_control">
      <robotNamespace>/</robotNamespace>
    </plugin>
    <plugin filename="libridgeback_ros_force_based_move.so" name="ridgeback_ros_force_based_move">
      <robotNamespace>/</robotNamespace>
      <commandTopic>cmd_vel</commandTopic>
      <odometryTopic>odom</odometryTopic>
      <odometryFrame>odom</odometryFrame>
      <odometryRate>25.0</odometryRate>
      <robotBaseFrame>base_link</robotBaseFrame>
      <cmdVelTimeOut>0.25</cmdVelTimeOut>
      <!-- Don't publish a transform: the controller does it. -->
      <publishOdometryTf>0</publishOdometryTf>
      <yaw_velocity_p_gain>500.0</yaw_velocity_p_gain>
      <x_velocity_p_gain>10000.0</x_velocity_p_gain>
      <y_velocity_p_gain>10000.0</y_velocity_p_gain>
    </plugin>
    <!--<plugin name="imu_controller" filename="libhector_gazebo_ros_imu.so">-->
    <!--<robotNamespace>/</robotNamespace>-->
    <!--<updateRate>50.0</updateRate>-->
    <!--<bodyName>imu_link</bodyName>-->
    <!--<topicName>imu/data</topicName>-->
    <!--<accelDrift>0.005 0.005 0.005</accelDrift>-->
    <!--<accelGaussianNoise>0.005 0.005 0.005</accelGaussianNoise>-->
    <!--<rateDrift>0.00005 0.00005 0.00005</rateDrift>-->
    <!--<rateGaussianNoise>0.00005 0.00005 0.00005</rateGaussianNoise>-->
    <!--<headingDrift>0.005</headingDrift>-->
    <!--<headingGaussianNoise>0.005</headingGaussianNoise>-->
    <!--</plugin>-->
    <!--ALLSO BAD EGG - need more efforts-->
    <!--<plugin name="gazebo_ros_joint_state_publisher" filename="libgazebo_ros_joint_state_publisher.so">-->
    <!--<jointName>wheel_FL_link</jointName>-->
    <!--<robotNamespace>/</robotNamespace>-->
    <!--<updateRate>50.0</updateRate>-->
    <!--</plugin>-->
  </gazebo>
  <!-- ///////////////////////-->
  <!-- Mechanum wheels chassis-->
  <!-- ///////////////////////-->
  <gazebo reference="base_link">
    <!--<mu1 value="1.0"/>-->
    <!--<mu2 value="1.0"/>-->
    <!--<kp value="10000000.0"/>-->
    <!--<kd value="1.0"/>-->
    <material>Gazebo/White</material>
    <gravity>true</gravity>
  </gazebo>
  <!--<gazebo reference="FL_wheel_link">-->
  <!--<mu1 value="0.0"/>-->
  <!--<mu2 value="0.0"/>-->
  <!--<kp value="10000000.0"/>-->
  <!--<kd value="1.0"/>-->
  <!--<material>Gazebo/Blue</material>-->
  <!--</gazebo>-->
  <!--<gazebo reference="FR_wheel_link">-->
  <!--<mu1 value="0.0"/>-->
  <!--<mu2 value="0.0"/>-->
  <!--<kp value="10000000.0"/>-->
  <!--<kd value="1.0"/>-->
  <!--<material>Gazebo/Blue</material>-->
  <!--</gazebo>-->
  <!--<gazebo reference="RL_wheel_link">-->
  <!--<mu1 value="0.0"/>-->
  <!--<mu2 value="0.0"/>-->
  <!--<kp value="10000000.0"/>-->
  <!--<kd value="1.0"/>-->
  <!--<material>Gazebo/Blue</material>-->
  <!--</gazebo>-->
  <!--<gazebo reference="RR_wheel_link">-->
  <!--<mu1 value="0.0"/>-->
  <!--<mu2 value="0.0"/>-->
  <!--<kp value="10000000.0"/>-->
  <!--<kd value="1.0"/>-->
  <!--<material>Gazebo/Blue</material>-->
  <!--</gazebo>-->
  <gazebo reference="wheel_FL_link">
    <mu1 value="0.0"/>
    <mu2 value="0.0"/>
    <kp value="10000000.0"/>
    <kd value="1.0"/>
    <material>Gazebo/Blue</material>
  </gazebo>
  <gazebo reference="wheel_FR_link">
    <mu1 value="0.0"/>
    <mu2 value="0.0"/>
    <kp value="10000000.0"/>
    <kd value="1.0"/>
    <material>Gazebo/Blue</material>
  </gazebo>
  <gazebo reference="wheel_RL_link">
    <mu1 value="0.0"/>
    <mu2 value="0.0"/>
    <kp value="10000000.0"/>
    <kd value="1.0"/>
    <material>Gazebo/Blue</material>
  </gazebo>
  <gazebo reference="wheel_RR_link">
    <mu1 value="0.0"/>
    <mu2 value="0.0"/>
    <kp value="10000000.0"/>
    <kd value="1.0"/>
    <material>Gazebo/Blue</material>
  </gazebo>
  <gazebo reference="motor_holder_base_RL_joint">
    <mu1 value="1.0"/>
    <mu2 value="1.0"/>
    <kp value="10000000.0"/>
    <kd value="1.0"/>
    <material>Gazebo/Red</material>
  </gazebo>
  <gazebo reference="motor_holder_RL">
    <mu1 value="1.0"/>
    <mu2 value="1.0"/>
    <kp value="10000000.0"/>
    <kd value="1.0"/>
    <material>Gazebo/Red</material>
  </gazebo>
  <gazebo reference="wheel_motor_RL_joint">
    <mu1 value="1.0"/>
    <mu2 value="1.0"/>
    <kp value="10000000.0"/>
    <kd value="1.0"/>
    <material>Gazebo/Red</material>
  </gazebo>
  <!--<gazebo reference="motor_holder_base_RL_joint">-->
  <!--<mu1 value="1.0"/>-->
  <!--<mu2 value="1.0"/>-->
  <!--<kp value="10000000.0"/>-->
  <!--<kd value="1.0"/>-->
  <!--<material>Gazebo/Red</material>-->
  <!--</gazebo>-->
  <!--<gazebo reference="motor_RR_holder">-->
  <!--<mu1 value="1.0"/>-->
  <!--<mu2 value="1.0"/>-->
  <!--<kp value="10000000.0"/>-->
  <!--<kd value="1.0"/>-->
  <!--<material>Gazebo/Red</material>-->
  <!--</gazebo>-->
  <!--<gazebo reference="motor_RR_holder">-->
  <!--<mu1 value="1.0"/>-->
  <!--<mu2 value="1.0"/>-->
  <!--<kp value="10000000.0"/>-->
  <!--<kd value="1.0"/>-->
  <!--<material>Gazebo/Red</material>-->
  <!--</gazebo>-->
  <!--<gazebo reference="motor_RR_holder">-->
  <!--<mu1 value="1.0"/>-->
  <!--<mu2 value="1.0"/>-->
  <!--<kp value="10000000.0"/>-->
  <!--<kd value="1.0"/>-->
  <!--<material>Gazebo/Red</material>-->
  <!--</gazebo>-->
  <!--<gazebo reference="motor_FL_holder">-->
  <!--<mu1 value="1.0"/>-->
  <!--<mu2 value="1.0"/>-->
  <!--<kp value="10000000.0"/>-->
  <!--<kd value="1.0"/>-->
  <!--<material>Gazebo/Red</material>-->
  <!--</gazebo>-->
  <!--<gazebo reference="motor_RL_holder">-->
  <!--<mu1 value="1.0"/>-->
  <!--<mu2 value="1.0"/>-->
  <!--<kp value="10000000.0"/>-->
  <!--<kd value="1.0"/>-->
  <!--<material>Gazebo/Red</material>-->
  <!--</gazebo>-->
  <!--<gazebo reference="motor_RR_holder">-->
  <!--<mu1 value="1.0"/>-->
  <!--<mu2 value="1.0"/>-->
  <!--<kp value="10000000.0"/>-->
  <!--<kd value="1.0"/>-->
  <!--<material>Gazebo/Red</material>-->
  <!--</gazebo>-->
  <!--<gazebo reference="FR_motor_holder">-->
  <!--<mu1 value="1.0"/>-->
  <!--<mu2 value="1.0"/>-->
  <!--<kp value="10000000.0"/>-->
  <!--<kd value="1.0"/>-->
  <!--<material>Gazebo/Red</material>-->
  <!--</gazebo>-->
  <!--<gazebo reference="FL_motor_holder">-->
  <!--<mu1 value="1.0"/>-->
  <!--<mu2 value="1.0"/>-->
  <!--<kp value="10000000.0"/>-->
  <!--<kd value="1.0"/>-->
  <!--<material>Gazebo/Red</material>-->
  <!--</gazebo>-->
  <!--<gazebo reference="RL_motor_holder">-->
  <!--<mu1 value="1.0"/>-->
  <!--<mu2 value="1.0"/>-->
  <!--<kp value="10000000.0"/>-->
  <!--<kd value="1.0"/>-->
  <!--<material>Gazebo/Red</material>-->
  <!--</gazebo>-->
  <!--<gazebo reference="RR_motor_holder">-->
  <!--<mu1 value="1.0"/>-->
  <!--<mu2 value="1.0"/>-->
  <!--<kp value="10000000.0"/>-->
  <!--<kd value="1.0"/>-->
  <!--<material>Gazebo/Red</material>-->
  <!--</gazebo>-->
  <!--&lt;!&ndash; ///////////////////////&ndash;&gt;-->
  <!--&lt;!&ndash;          Body          &ndash;&gt;-->
  <!--&lt;!&ndash; ///////////////////////&ndash;&gt;-->
  <!--<gazebo reference="body">-->
  <!--<mu1 value="1.0"/>-->
  <!--<mu2 value="1.0"/>-->
  <!--<kp value="10000000.0"/>-->
  <!--<kd value="1.0"/>-->
  <!--<material>Gazebo/White</material>-->
  <!--</gazebo>-->
  <!--<gazebo reference="back_cover">-->
  <!--<mu1 value="1.0"/>-->
  <!--<mu2 value="1.0"/>-->
  <!--<kp value="10000000.0"/>-->
  <!--<kd value="1.0"/>-->
  <!--<material>Gazebo/White</material>-->
  <!--</gazebo>-->
  <!--&lt;!&ndash; ///////////////////////&ndash;&gt;-->
  <!--&lt;!&ndash;          Head          &ndash;&gt;-->
  <!--&lt;!&ndash; ///////////////////////&ndash;&gt;-->
  <!--<gazebo reference="head">-->
  <!--<mu1 value="1.0"/>-->
  <!--<mu2 value="1.0"/>-->
  <!--<kp value="10000000.0"/>-->
  <!--<kd value="1.0"/>-->
  <!--<material>Gazebo/White</material>-->
  <!--</gazebo>-->
  <!--<gazebo reference="tray">-->
  <!--<mu1 value="1.0"/>-->
  <!--<mu2 value="1.0"/>-->
  <!--<kp value="10000000.0"/>-->
  <!--<kd value="1.0"/>-->
  <!--<material>Gazebo/White</material>-->
  <!--</gazebo>-->
  <!--<gazebo reference="monitor">-->
  <!--<mu1 value="1.0"/>-->
  <!--<mu2 value="1.0"/>-->
  <!--<kp value="10000000.0"/>-->
  <!--<kd value="1.0"/>-->
  <!--<material>Gazebo/White</material>-->
  <!--</gazebo>-->
  <!--THIS ONE IS BEING SKIPPED!!! (by parser)-->
  <!-- This is an wheel-level solution to possibly revisit at a future date. -->
  <!--<gazebo>-->
  <!--<rosparam param="/gazebo_ros_control/pid_gains">-->
  <!--wheel_motor_FL_joint:-->
  <!--p: 1-->
  <!--i: 0.1-->
  <!--d: 0-->
  <!--wheel_motor_FR_joint:-->
  <!--p: 1-->
  <!--i: 0.1-->
  <!--d: 0-->
  <!--wheel_motor_RL_joint:-->
  <!--p: 1-->
  <!--i: 0.1-->
  <!--d: 0-->
  <!--wheel_motor_RR_joint:-->
  <!--p: 1-->
  <!--i: 0.1-->
  <!--d: 0-->
  <!--</rosparam>-->
  <!--</gazebo>-->
  <!---->
  <!--ULTRASONIC-->
  <!--<xacro:ultrasonic_gazebo position="FRONT_TOP"/>-->
  <!--<xacro:ultrasonic_gazebo position="FRONT_BOTTOM"/>-->
  <!--<xacro:ultrasonic_gazebo position="FRONT_BOTTOM_LEFT"/>-->
  <!--<xacro:ultrasonic_gazebo position="FRONT_BOTTOM_RIGHT"/>-->
  <!--<xacro:ultrasonic_gazebo position="RIGHT_TOP"/>-->
  <!--<xacro:ultrasonic_gazebo position="RIGHT_BOTTOM"/>-->
  <!--<xacro:ultrasonic_gazebo position="RIGHT_BOTTOM_SIDE"/>-->
  <!--<xacro:ultrasonic_gazebo position="SIDE_TOP"/>-->
  <!--<xacro:ultrasonic_gazebo position="SIDE_BOTTOM"/>-->
  <!--<xacro:ultrasonic_gazebo position="SIDE_BOTTOM_LEFT"/>-->
  <!--<xacro:ultrasonic_gazebo position="LEFT_TOP"/>-->
  <!--<xacro:ultrasonic_gazebo position="LEFT_BOTTOM"/>-->
  <!---->
  <!---->
  <!---->
  <!--RANGE SENSOR-->
  <!--<xacro:range_sensor_gazebo position="FRONT_FIRST"/>-->
  <!--<xacro:range_sensor_gazebo position="FRONT_SECOND"/>-->
  <!--<xacro:range_sensor_gazebo position="FRONT_THIRD"/>-->
  <!--<xacro:range_sensor_gazebo position="RIGHT_FIRST"/>-->
  <!--<xacro:range_sensor_gazebo position="RIGHT_SECOND"/>-->
  <!--<xacro:range_sensor_gazebo position="RIGHT_THIRD"/>-->
  <!--<xacro:range_sensor_gazebo position="SIDE_FIRST"/>-->
  <!--<xacro:range_sensor_gazebo position="SIDE_SECOND"/>-->
  <!--<xacro:range_sensor_gazebo position="SIDE_THIRD"/>-->
  <!--<xacro:range_sensor_gazebo position="LEFT_FIRST"/>-->
  <!--<xacro:range_sensor_gazebo position="LEFT_SECOND"/>-->
  <!--<xacro:range_sensor_gazebo position="LEFT_THIRD"/>-->
  <!---->
  <!---->
</robot>

